<?xml version="1.0"?>
<robot xmlns:xacro="http://ros.org/wiki/xacro">
  <xacro:arg name="is_sim" default="false"/>
  <xacro:arg name="use_fake_hardware" default="false"/>
  <xacro:arg name="use_manipulation_controllers" default="false"/>

  <xacro:macro name="kinova_gen3_6dof" params="
    name
    parent_link
    *origin
    tf_prefix:=''
    dof:=6
    vision:=false
    robot_ip:=192.168.131.40
    username:=admin
    password:=admin
    port:=10000
    port_realtime:=10001
    session_inactivity_timeout_ms:=6000
    connection_inactivity_timeout_ms:=2000
    use_internal_bus_gripper_comm:=false
    gripper_joint_name:=finger_joint
    gripper_max_velocity:=100.0
    gripper_max_force:=100.0
    use_fake_hardware:=$(arg use_fake_hardware)
    use_controllers:=$(arg use_manipulation_controllers)
    fake_sensor_commands:=false
    sim_gazebo:=false
    sim_ignition:=$(arg is_sim)
    sim_isaac:=false
    use_external_cable:=false
    initial_positions:=${dict(joint_1=0.0,joint_2=0.0,joint_3=0.0,joint_4=0.0,joint_5=0.0,joint_6=0.0)}" >

    <!-- Instantiate the Arm -->
    <joint name="${name}_base_joint" type="fixed">
      <xacro:insert_block name="origin" />
      <parent link="${parent_link}"/>
      <child link="${name}_base_link" />
    </joint>
    <link name="${name}_base_link">
      <inertial>
        <origin xyz="-0.000648 -0.000166 0.084487" rpy="0 0 0" />
        <mass value="1.697" />
        <inertia ixx="0.004622" ixy="9E-06" ixz="6E-05" iyy="0.004495" iyz="9E-06" izz="0.002079" />
      </inertial>
      <visual>
        <origin xyz="0 0 0" rpy="0 0 0" />
        <geometry>
          <mesh filename="file://$(find kortex_description)/arms/gen3/${dof}dof/meshes/base_link.STL" />
        </geometry>
        <material name="">
          <color rgba="0.75294 0.75294 0.75294 1" />
        </material>
      </visual>
      <collision>
        <origin xyz="0 0 0" rpy="0 0 0" />
        <geometry>
          <mesh filename="file://$(find kortex_description)/arms/gen3/${dof}dof/meshes/base_link.STL" />
        </geometry>
      </collision>
    </link>
    <link name="${name}_shoulder_link">
      <inertial>
        <origin xyz="-2.3E-05 -0.010364 -0.07336" rpy="0 0 0" />
        <mass value="1.377" />
        <inertia ixx="0.00457" ixy="1E-06" ixz="2E-06" iyy="0.004831" iyz="0.000448" izz="0.001409" />
      </inertial>
      <visual>
        <origin xyz="0 0 0" rpy="0 0 0" />
        <geometry>
          <mesh filename="file://$(find kortex_description)/arms/gen3/${dof}dof/meshes/shoulder_link.STL" />
        </geometry>
        <material name="">
          <color rgba="0.75294 0.75294 0.75294 1" />
        </material>
      </visual>
      <collision>
        <origin xyz="0 0 0" rpy="0 0 0" />
        <geometry>
          <mesh filename="file://$(find kortex_description)/arms/gen3/${dof}dof/meshes/shoulder_link.STL" />
        </geometry>
      </collision>
    </link>
    <xacro:if value="${use_external_cable}">
      <joint
        name="${name}_joint_1"
        type="revolute">
        <origin
          xyz="0 0 0.15643"
          rpy="-3.1416 0.0 0.0" />
        <parent link="${name}_base_link" />
        <child link="${name}_shoulder_link" />
        <axis xyz="0 0 1" />
        <limit
          lower="${-2*math.pi}"
          upper="${2*math.pi}"
          effort="39"
          velocity="1.3963" />
      </joint>
    </xacro:if>
    <xacro:unless value="${use_external_cable}">
      <joint
        name="${name}_joint_1"
        type="continuous">
        <origin
          xyz="0 0 0.15643"
          rpy="-3.1416 0.0 0.0" />
        <parent link="${name}_base_link" />
        <child link="${name}_shoulder_link" />
        <axis xyz="0 0 1" />
        <limit
          effort="39"
          velocity="1.3963" />
      </joint>
    </xacro:unless>

    <link name="${name}_bicep_link">
      <inertial>
        <origin
          xyz="3.5E-05 -0.208207 -0.01889"
          rpy="0 0 0" />
        <mass value="1.262" />
        <inertia
          ixx="0.046752"
          ixy="-9E-06"
          ixz="0"
          iyy="0.00085"
          iyz="-9.8E-05"
          izz="0.047188" />
      </inertial>
      <visual>
        <origin
          xyz="0 0 0"
          rpy="0 0 0" />
        <geometry>
          <mesh filename="file://$(find kortex_description)/arms/gen3/${dof}dof/meshes/bicep_link.STL" />
        </geometry>
        <material name="">
          <color rgba="0.75294 0.75294 0.75294 1" />
        </material>
      </visual>
      <collision>
        <origin
          xyz="0 0 0"
          rpy="0 0 0" />
        <geometry>
          <mesh filename="file://$(find kortex_description)/arms/gen3/${dof}dof/meshes/bicep_link.STL" />
        </geometry>
      </collision>
    </link>
    <joint name="${name}_joint_2" type="revolute">
      <origin xyz="0 0.005375 -0.12838" rpy="1.5708 0.0 0.0" />
      <parent link="${name}_shoulder_link" />
      <child link="${name}_bicep_link" />
      <axis xyz="0 0 1" />
      <limit lower="-2.41" upper="2.41" effort="39" velocity="1.3963" />
    </joint>
    <link name="${name}_forearm_link">
      <inertial>
        <origin xyz="1.8E-05 0.076168 -0.01397" rpy="0 0 0" />
        <mass value="0.93" />
        <inertia ixx="0.008292" ixy="-1E-06" ixz="0" iyy="0.000628" iyz="0.000432" izz="0.008464" />
      </inertial>
      <visual>
        <origin xyz="0 0 0" rpy="0 0 0" />
        <geometry>
          <mesh filename="file://$(find kortex_description)/arms/gen3/${dof}dof/meshes/forearm_link.STL" />
        </geometry>
        <material name="">
          <color rgba="0.75294 0.75294 0.75294 1" />
        </material>
      </visual>
      <collision>
        <origin xyz="0 0 0" rpy="0 0 0" />
        <geometry>
          <mesh filename="file://$(find kortex_description)/arms/gen3/${dof}dof/meshes/forearm_link.STL" />
        </geometry>
      </collision>
    </link>
    <joint name="${name}_joint_3" type="revolute">
      <origin xyz="0 -0.41 0" rpy="3.1416 0 0" />
      <parent link="${name}_bicep_link" />
      <child link="${name}_forearm_link" />
      <axis xyz="0 0 1" />
      <limit lower="-2.66" upper="2.66" effort="39" velocity="1.3963" />
    </joint>
    <link name="${name}_spherical_wrist_1_link">
      <inertial>
        <origin xyz="-1E-06 0.008486 -0.062937" rpy="0 0 0" />
        <mass value="0.6781" />
        <inertia ixx="0.001645" ixy="0" ixz="0" iyy="0.001666" iyz="-0.000234" izz="0.000389" />
      </inertial>
      <visual>
        <origin xyz="0 0 0" rpy="0 0 0" />
        <geometry>
          <mesh filename="file://$(find kortex_description)/arms/gen3/${dof}dof/meshes/spherical_wrist_1_link.STL" />
        </geometry>
        <material name="">
          <color rgba="0.75294 0.75294 0.75294 1" />
        </material>
      </visual>
      <collision>
        <origin xyz="0 0 0" rpy="0 0 0" />
        <geometry>
          <mesh filename="file://$(find kortex_description)/arms/gen3/${dof}dof/meshes/spherical_wrist_1_link.STL" />
        </geometry>
      </collision>
    </link>
    <xacro:if value="${use_external_cable}">
      <joint name="${name}_joint_4" type="revolute">
        <origin xyz="0 0.20843 -0.006375" rpy="1.5708 0.0 0.0" />
        <parent link="${name}_forearm_link" />
        <child link="${name}_spherical_wrist_1_link" />
        <axis xyz="0 0 1" />
        <limit lower="${-2*math.pi}" upper="${2*math.pi}" effort="9" velocity="1.2218" />
      </joint>
    </xacro:if>
    <xacro:unless value="${use_external_cable}">
      <joint name="${name}_joint_4" type="continuous">
        <origin xyz="0 0.20843 -0.006375" rpy="1.5708 0.0 0.0" />
        <parent link="${name}_forearm_link" />
        <child link="${name}_spherical_wrist_1_link" />
        <axis xyz="0 0 1" />
        <limit effort="9" velocity="1.2218" />
      </joint>
    </xacro:unless>
    <link name="${name}_spherical_wrist_2_link">
      <inertial>
        <origin xyz="-1E-06 0.046429 -0.008704" rpy="0 0 0" />
        <mass value="0.678" />
        <inertia ixx="0.001685" ixy="0" ixz="0" iyy="0.0004" iyz="0.000255" izz="0.001696" />
      </inertial>
      <visual>
        <origin xyz="0 0 0" rpy="0 0 0" />
        <geometry>
          <mesh filename="file://$(find kortex_description)/arms/gen3/${dof}dof/meshes/spherical_wrist_2_link.STL" />
        </geometry>
        <material name="">
          <color rgba="0.75294 0.75294 0.75294 1" />
        </material>
      </visual>
      <collision>
        <origin xyz="0 0 0" rpy="0 0 0" />
        <geometry>
          <mesh filename="file://$(find kortex_description)/arms/gen3/${dof}dof/meshes/spherical_wrist_2_link.STL" />
        </geometry>
      </collision>
    </link>
    <joint name="${name}_joint_5" type="revolute">
      <origin xyz="0 -0.00017505 -0.10593" rpy="-1.5708 0.0 0.0" />
      <parent link="${name}_spherical_wrist_1_link" />
      <child link="${name}_spherical_wrist_2_link" />
      <axis xyz="0 0 1" />
      <limit lower="-2.23" upper="2.23" effort="9" velocity="1.2218" />
    </joint>
    <!-- Bracelet with Vision -->
    <xacro:if value="${vision}">
      <link name="${name}_bracelet_link">
        <inertial>
          <origin xyz="0.000281 0.011402 -0.029798" rpy="0 0 0" />
          <mass value="0.5" />
          <inertia ixx="0.000587" ixy="3E-06" ixz="3E-06" iyy="0.000369" iyz="-0.000118" izz="0.000609" />
        </inertial>
        <visual>
          <origin xyz="0 0 0" rpy="0 0 0" />
          <geometry>
            <mesh filename="file://$(find kortex_description)/arms/gen3/${dof}dof/meshes/bracelet_with_vision_link.STL" />
          </geometry>
          <material name="">
            <color rgba="0.75294 0.75294 0.75294 1" />
          </material>
        </visual>
        <collision>
          <origin xyz="0 0 0" rpy="0 0 0" />
          <geometry>
            <mesh filename="file://$(find kortex_description)/arms/gen3/${dof}dof/meshes/bracelet_with_vision_link.STL" />
          </geometry>
        </collision>
      </link>
    </xacro:if>
    <!-- Bracelet without Vision -->
    <xacro:unless value="${vision}">
      <link name="${name}_bracelet_link">
        <inertial>
          <origin xyz="-9.3E-05 0.000132 -0.022905" rpy="0 0 0" />
          <mass value="0.364" />
          <inertia ixx="0.000214" ixy="0" ixz="1E-06" iyy="0.000223" iyz="-2E-06" izz="0.00024" />
        </inertial>
        <visual>
          <origin xyz="0 0 0" rpy="0 0 0" />
          <geometry>
            <mesh filename="file://$(find kortex_description)/arms/gen3/${dof}dof/meshes/bracelet_no_vision_link.STL" />
          </geometry>
          <material name="">
            <color rgba="0.75294 0.75294 0.75294 1" />
          </material>
        </visual>
        <collision>
          <origin xyz="0 0 0" rpy="0 0 0" />
          <geometry>
            <mesh filename="file://$(find kortex_description)/arms/gen3/${dof}dof/meshes/bracelet_no_vision_link.STL" />
          </geometry>
        </collision>
      </link>
    </xacro:unless>
    <!-- Limit Wrist if using External Cable -->
    <xacro:if value="${use_external_cable}">
      <joint name="${name}_joint_6" type="revolute">
        <origin xyz="0 0.10593 -0.00017505" rpy="1.5708 0.0 0.0" />
        <parent link="${name}_spherical_wrist_2_link" />
        <child link="${name}_bracelet_link" />
        <axis xyz="0 0 1" />
        <limit lower="${-2*math.pi}" upper="${2*math.pi}" effort="9" velocity="1.2218" />
      </joint>
    </xacro:if>
    <xacro:unless value="${use_external_cable}">
      <joint name="${name}_joint_6" type="continuous">
        <origin xyz="0 0.10593 -0.00017505" rpy="1.5708 0.0 0.0" />
        <parent link="${name}_spherical_wrist_2_link" />
        <child link="${name}_bracelet_link" />
        <axis xyz="0 0 1" />
        <limit effort="9" velocity="1.2218" />
      </joint>
    </xacro:unless>
    <link name="${name}_end_effector_link" />
    <joint
      name="${name}_end_effector"
      type="fixed">
      <origin xyz="0 0 -0.0615250000000001" rpy="3.14159265358979 1.09937075168372E-32 3.14159265358979" />
      <parent
        link="${name}_bracelet_link" />
      <child
        link="${name}_end_effector_link" />
      <axis
        xyz="0 0 0" />
    </joint>

    <!-- Vision -->
    <xacro:if value="${vision}">
      <!-- TODO(destogl) this probably collides with camera URDF -->
      <link name="${name}_camera_link" />
      <joint name="${name}_camera_module" type="fixed">
        <origin xyz="0 0.05639 -0.00305" rpy="3.14159265358979 3.14159265358979 0" />
        <parent link="${name}_end_effector_link" />
        <child  link="${name}_camera_link" />
      </joint>
      <link name="${name}_camera_depth_frame" />
      <joint name="${name}_depth_module" type="fixed">
        <origin xyz="0.0275 0.066 -0.00305" rpy="3.14159265358979 3.14159265358979 0" />
        <parent link="${name}_end_effector_link" />
        <child  link="${name}_camera_depth_frame" />
      </joint>
      <link name="${name}_camera_color_frame" />
      <joint name="${name}_color_module" type="fixed">
        <origin xyz="0 0.05639 -0.00305" rpy="3.14159265358979 3.14159265358979 0" />
        <parent link="${name}_end_effector_link" />
        <child  link="${name}_camera_color_frame" />
      </joint>
    </xacro:if>

    <!-- ROS2 Controls -->
    <xacro:if value="${use_controllers}">
      <ros2_control name="${name}_hardware" type="system">
        <hardware>
          <xacro:if value="${sim_gazebo}">
            <plugin>gazebo_ros2_control/GazeboSystem</plugin>
          </xacro:if>
          <xacro:if value="${sim_ignition}">
            <plugin>ign_ros2_control/IgnitionSystem</plugin>
          </xacro:if>
          <xacro:if value="${sim_isaac}">
            <plugin>topic_based_ros2_control/TopicBasedSystem</plugin>
            <param name="joint_commands_topic">/isaac_joint_commands</param>
            <param name="joint_states_topic">/isaac_joint_states</param>
          </xacro:if>
          <xacro:if value="${use_fake_hardware}">
            <plugin>fake_components/GenericSystem</plugin>
            <param name="fake_sensor_commands">${fake_sensor_commands}</param>
            <param name="state_following_offset">0.0</param>
          </xacro:if>
          <xacro:unless value="${use_fake_hardware or sim_gazebo or sim_ignition or sim_isaac}">
            <plugin>kortex_driver/KortexMultiInterfaceHardware</plugin>
            <param name="robot_ip">${robot_ip}</param>
            <param name="username">${username}</param>
            <param name="password">${password}</param>
            <param name="port">${port}</param>
            <param name="port_realtime">${port_realtime}</param>
            <param name="session_inactivity_timeout_ms">${session_inactivity_timeout_ms}</param>
            <param name="connection_inactivity_timeout_ms">${connection_inactivity_timeout_ms}</param>
            <param name="tf_prefix">"${tf_prefix}"</param>
            <param name="use_internal_bus_gripper_comm">${use_internal_bus_gripper_comm}</param>
            <param name="gripper_joint_name">${gripper_joint_name}</param>
            <param name="gripper_max_velocity">${gripper_max_velocity}</param>
            <param name="gripper_max_force">${gripper_max_force}</param>
          </xacro:unless>
        </hardware>
        <joint name="${name}_joint_1">
          <command_interface name="position">
            <param name="min">{-2*pi}</param>
            <param name="max">{2*pi}</param>
          </command_interface>
          <command_interface name="velocity">
            <param name="min">-3.15</param>
            <param name="max">3.15</param>
          </command_interface>
          <state_interface name="position">
            <param name="initial_value">${initial_positions['joint_1']}</param>
          </state_interface>
          <state_interface name="velocity"/>
          <state_interface name="effort"/>
        </joint>
        <joint name="${name}_joint_2">
          <command_interface name="position">
            <param name="min">-2.41</param>
            <param name="max">2.41</param>
          </command_interface>
          <command_interface name="velocity">
            <param name="min">-3.15</param>
            <param name="max">3.15</param>
          </command_interface>
          <state_interface name="position">
            <param name="initial_value">${initial_positions['joint_2']}</param>
          </state_interface>
          <state_interface name="velocity"/>
          <state_interface name="effort"/>
        </joint>
        <joint name="${name}_joint_3">
          <command_interface name="position">
            <param name="min">-2.66</param>
            <param name="max">2.66</param>
          </command_interface>
          <command_interface name="velocity">
            <param name="min">-3.2</param>
            <param name="max">3.2</param>
          </command_interface>
          <state_interface name="position">
            <param name="initial_value">${initial_positions['joint_3']}</param>
          </state_interface>
          <state_interface name="velocity"/>
          <state_interface name="effort"/>
        </joint>
        <joint name="${name}_joint_4">
          <command_interface name="position">
            <param name="min">{-2*pi}</param>
            <param name="max">{2*pi}</param>
          </command_interface>
          <command_interface name="velocity">
            <param name="min">-3.2</param>
            <param name="max">3.2</param>
          </command_interface>
          <state_interface name="position">
            <param name="initial_value">${initial_positions['joint_4']}</param>
          </state_interface>
          <state_interface name="velocity"/>
          <state_interface name="effort"/>
        </joint>
        <joint name="${name}_joint_5">
          <command_interface name="position">
            <param name="min">-2.23</param>
            <param name="max">2.23</param>
          </command_interface>
          <command_interface name="velocity">
            <param name="min">-3.2</param>
            <param name="max">3.2</param>
          </command_interface>
          <state_interface name="position">
            <param name="initial_value">${initial_positions['joint_5']}</param>
          </state_interface>
          <state_interface name="velocity"/>
          <state_interface name="effort"/>
        </joint>
        <joint name="${name}_joint_6">
          <command_interface name="position">
            <param name="min">{-2*pi}</param>
            <param name="max">{2*pi}</param>
          </command_interface>
          <command_interface name="velocity">
            <param name="min">-3.2</param>
            <param name="max">3.2</param>
          </command_interface>
          <state_interface name="position">
            <param name="initial_value">${initial_positions['joint_6']}</param>
          </state_interface>
          <state_interface name="velocity"/>
          <state_interface name="effort"/>
        </joint>
        <xacro:unless value="${use_fake_hardware or sim_gazebo or sim_ignition or sim_isaac}">
          <xacro:if value="${use_internal_bus_gripper_comm}">
            <joint name="${name}_${gripper_joint_name}">
              <command_interface name="position" />
              <state_interface name="position"/>
              <state_interface name="velocity"/>
            </joint>
          </xacro:if>
        </xacro:unless>
      </ros2_control>
    </xacro:if>

    <!-- Gazebo Plug-in -->
    <xacro:if value="${sim_ignition}">
      <gazebo>
        <plugin filename="libignition-gazebo-sensors-system.so" name="ignition::gazebo::systems::Sensors">
          <render_engine>ogre2</render_engine>
        </plugin>
      </gazebo>
      <gazebo reference="camera_color_frame">
        <sensor name="camera_sensor" type="rgbd_camera">
          <camera>
            <horizontal_fov>1.047</horizontal_fov>
            <image>
              <width>640</width>
              <height>480</height>
              <format>RGB_INT8</format>
            </image>
            <clip>
              <near>0.1</near>
              <far>5</far>
            </clip>
            <distortion>
              <k1>0.0</k1>
              <k2>0.0</k2>
              <k3>0.0</k3>
              <p1>0.0</p1>
              <p2>0.0</p2>
              <center>0.5 0.5</center>
            </distortion>
            <lens>
              <intrinsics>
                <fx>554.25469</fx>
                <fy>554.25469</fy>
                <cx>320.5</cx>
                <cy>240.5</cy>
                <s>0</s>
              </intrinsics>
              <projection>
                <p_fx>554.25469</p_fx>
                <p_fy>554.25469</p_fy>
                <p_cx>320.5</p_cx>
                <p_cy>240.5</p_cy>
                <tx>0</tx>
                <ty>0</ty>
              </projection>
            </lens>
            <noise>
              <type>gaussian</type>
              <mean>0</mean>
              <stddev>0.00</stddev>
            </noise>
            <depth_camera>
              <clip>
                <near>0.25</near>
                <far>5</far>
              </clip>
            </depth_camera>
            <optical_frame_id>color_optical_frame</optical_frame_id>
          </camera>
          <ignition_frame_id>camera_color_frame</ignition_frame_id>
          <always_on>1</always_on>
          <update_rate>6</update_rate>
          <visualize>true</visualize>
          <topic>wrist_mounted_camera</topic>
          <enable_metrics>false</enable_metrics>
        </sensor>
      </gazebo>
    </xacro:if>
  </xacro:macro>

</robot>
