<?xml version="1.0"?>
<robot xmlns:xacro="http://ros.org/wiki/xacro" name="do100_wheel">

  <xacro:macro name="do100_wheel" params="prefix *joint_pose">

    <link name="${prefix}_wheel_link">
      <visual>
        <origin xyz="0 0 0" rpy="${PI/2} 0 0"/>
        <geometry>
          <cylinder radius="${wheel_radius}" length="${wheel_width}"/>
        </geometry>
        <material name="clearpath_black" />
      </visual>
      <collision>
        <origin xyz="0 0 0" rpy="${PI/2} 0 0"/>
        <geometry>
          <cylinder radius="${wheel_radius}" length="${wheel_width}"/>
        </geometry>
      </collision>
      <inertial>
        <origin xyz="0 0 0" rpy="0 0 0"/>
        <mass value="${wheel_mass}"/>
        <inertia
          ixx="0.0003234" ixy="0" ixz="0"
          iyy="0.0003234" iyz="0"
          izz="0.0004901"/>
      </inertial>
    </link>

    <gazebo reference="${prefix}_wheel_link">
      <material>Gazebo/DarkGrey</material>
      <selfCollide>false</selfCollide>
      <mu1 value="0.5"/>
      <mu2 value="0.5"/>
      <!-- <fdir1 value="1 0 0"/> -->
    </gazebo>

    <joint name="${prefix}_wheel_joint" type="continuous">
      <parent link="chassis_link"/>
      <child link="${prefix}_wheel_link" />
      <xacro:insert_block name="joint_pose" />
      <axis xyz="0 1 0" />
    </joint>

  </xacro:macro>

</robot>
