<?xml version="1.0"?>
<robot name="robotiq_2f_140_model" xmlns:xacro="http://ros.org/wiki/xacro">
  <xacro:arg name="is_sim" default="false"/>
  <xacro:arg name="use_fake_hardware" default="false"/>
  <xacro:arg name="use_manipulation_controllers" default="false"/>

  <xacro:macro name="robotiq_2f_140" params="
    name
    parent_link
    *origin
    use_fake_hardware:=$(arg use_fake_hardware)
    use_controllers:=$(arg use_manipulation_controllers)
    fake_sensor_commands:=false
    sim_ignition:=$(arg is_sim)
    sim_gazebo:=false
    sim_isaac:=false
    isaac_joint_commands:=/isaac_joint_commands
    isaac_joint_states:=/isaac_joint_states
    com_port:=/dev/ttyUSB0">

    <!-- Variables Mappings -->
    <xacro:property name="prefix" value="${name}_"/>
    <xacro:property name="stroke" value="140"/>

    <!-- this is a temporary link to rotate the 2f-140 gripper to match the 2f-85 -->
    <link name="${prefix}robotiq_base_link"/>
    <joint name="${prefix}robotiq_base_joint" type="fixed">
      <parent link="${parent_link}" />
      <child link="${prefix}robotiq_base_link" />
      <origin xyz="0 0 0" rpy="0 0 ${pi/2}" />
    </joint>

    <link name="${prefix}robotiq_140_base_link">
      <inertial>
        <origin xyz="8.625E-08 -4.6583E-06 0.03145" rpy="0 0 0" />
        <mass value="0.22652" />
        <inertia ixx="0.00020005" ixy="-4.2442E-10" ixz="-2.9069E-10" iyy="0.00017832" iyz="-3.4402E-08" izz="0.00013478" />
      </inertial>
      <visual>
        <origin xyz="0 0 0" rpy="0 0 0" />
        <geometry>
          <mesh filename="file://$(find clearpath_manipulators_description)/meshes/gripper/robotiq_2f_140_base_link.stl" />
        </geometry>
        <material name="">
          <color rgba="0.1 0.1 0.1 1" />
        </material>
      </visual>
      <collision>
        <origin xyz="0 0 0" rpy="0 0 0" />
        <geometry>
          <mesh filename="file://$(find clearpath_manipulators_description)/meshes/gripper/robotiq_2f_140_base_link_collision.stl" />
        </geometry>
      </collision>
    </link>
    <joint name="${prefix}robotiq_140_base_joint" type="fixed">
      <parent link="${prefix}robotiq_base_link" />
      <child link="${prefix}robotiq_140_base_link" />
      <xacro:insert_block name="origin" />
    </joint>

    <!-- Macros -->
    <xacro:macro name="outer_knuckle" params="prefix fingerprefix stroke">
      <link name="${prefix}${fingerprefix}_outer_knuckle">
        <inertial>
          <origin xyz="-0.000200000000003065 0.0199435877845359 0.0292245259211331" rpy="0 0 0" />
          <mass value="0.00853198276973456" />
          <inertia
              ixx="2.89328108496468E-06"
              ixy="-1.57935047237397E-19"
              ixz="-1.93980378593255E-19"
              iyy="1.86719750325683E-06"
              iyz="-1.21858577871576E-06"
              izz="1.21905238907251E-06" />
        </inertial>
        <visual>
          <origin xyz="0 0 0" rpy="0 0 0" />
          <geometry>
            <mesh filename="file://$(find clearpath_manipulators_description)/meshes/gripper/robotiq_2f_${stroke}_outer_knuckle.stl" />
          </geometry>
          <material name="">
            <color rgba="0.792156862745098 0.819607843137255 0.933333333333333 1" />
          </material>
        </visual>
        <collision>
          <origin xyz="0 0 0" rpy="0 0 0" />
          <geometry>
            <mesh filename="file://$(find clearpath_manipulators_description)/meshes/gripper/robotiq_2f_${stroke}_outer_knuckle_collision.stl" />
          </geometry>
        </collision>
      </link>
    </xacro:macro>

    <xacro:macro name="outer_finger" params="prefix fingerprefix stroke">
      <link name="${prefix}${fingerprefix}_outer_finger">
        <inertial>
          <origin xyz="0.00030115855001899 0.0373907951953854 -0.0208027427000385" rpy="0 0 0" />
          <mass value="0.022614240507152" />
          <inertia
              ixx="1.52518312458174E-05"
              ixy="9.76583423954399E-10"
              ixz="-5.43838577022588E-10"
              iyy="6.17694243867776E-06"
              iyz="6.78636130740228E-06"
              izz="1.16494917907219E-05" />
        </inertial>
        <visual>
          <origin xyz="0 0 0" rpy="0 0 0" />
          <geometry>
            <mesh filename="file://$(find clearpath_manipulators_description)/meshes/gripper/robotiq_2f_${stroke}_outer_finger.stl" />
          </geometry>
          <material name="">
            <color rgba="0.1 0.1 0.1 1" />
          </material>
        </visual>
        <collision>
          <origin xyz="0 0 0" rpy="0 0 0" />
          <geometry>
            <mesh filename="file://$(find clearpath_manipulators_description)/meshes/gripper/robotiq_2f_${stroke}_outer_finger_collision.stl" />
          </geometry>
        </collision>
      </link>
    </xacro:macro>

    <xacro:macro name="inner_knuckle" params="prefix fingerprefix stroke">
      <link name="${prefix}${fingerprefix}_inner_knuckle">
        <inertial>
          <origin xyz="0.000123011831763771 0.0507850843201817 0.00103968640075166" rpy="0 0 0" />
          <mass value="0.0271177346495152" />
          <inertia
              ixx="2.61910379223783E-05"
              ixy="-2.43616858946494E-07"
              ixz="-6.37789906117123E-09"
              iyy="2.8270243746167E-06"
              iyz="-5.37200748039765E-07"
              izz="2.83695868220296E-05" />
        </inertial>
        <visual>
          <origin xyz="0 0 0" rpy="0 0 0" />
          <geometry>
            <mesh filename="file://$(find clearpath_manipulators_description)/meshes/gripper/robotiq_2f_${stroke}_inner_knuckle.stl" />
          </geometry>
          <material name="">
            <color rgba="0.1 0.1 0.1 1" />
          </material>
        </visual>
        <collision>
          <origin xyz="0 0 0" rpy="0 0 0" />
          <geometry>
            <mesh filename="file://$(find clearpath_manipulators_description)/meshes/gripper/robotiq_2f_${stroke}_inner_knuckle_collision.stl" />
          </geometry>
        </collision>
      </link>
    </xacro:macro>

    <xacro:macro name="inner_finger" params="prefix fingerprefix stroke">
      <link name="${prefix}${fingerprefix}_inner_finger">
        <inertial>
          <origin xyz="0.000299999999999317 0.0160078233491243 -0.0136945669206257" rpy="0 0 0" />
          <mass value="0.0104003125914103" />
          <inertia
              ixx="2.71909453810972E-06"
              ixy="1.35402465472579E-21"
              ixz="-7.1817349065269E-22"
              iyy="7.69100314106116E-07"
              iyz="6.74715432769696E-07"
              izz="2.30315190420171E-06" />
        </inertial>
        <visual>
          <origin xyz="0 0 0" rpy="0 0 0" />
          <geometry>
            <mesh filename="file://$(find clearpath_manipulators_description)/meshes/gripper/robotiq_2f_${stroke}_inner_finger.stl" />
          </geometry>
          <material name="">
            <color rgba="0.1 0.1 0.1 1" />
          </material>
        </visual>
        <collision>
          <origin xyz="0 0 0" rpy="0 0 0" />
          <geometry>
            <mesh filename="file://$(find clearpath_manipulators_description)/meshes/gripper/robotiq_2f_${stroke}_inner_finger_collision.stl" />
          </geometry>
        </collision>
      </link>
    </xacro:macro>

    <!-- Finger pad link, the default are the "big pads" with rubber-->
    <xacro:macro name="inner_finger_pad" params="prefix fingerprefix">
      <link name="${prefix}${fingerprefix}_inner_finger_pad">
        <visual>
          <origin xyz="0 0 0" rpy="0 0 0" />
          <geometry>
            <box size="0.027 0.065 0.0075"/>
          </geometry>
          <material name="">
            <color rgba="0.9 0.9 0.9 1" />
          </material>
        </visual>
        <collision>
          <origin xyz="0 0 0" rpy="0 0 0" />
          <geometry>
            <box size="0.03 0.07 0.0075"/>
          </geometry>
          <material name="">
            <color rgba="0.9 0.0 0.0 1" />
          </material>
        </collision>
      </link>
    </xacro:macro>

    <xacro:macro name="finger_joint" params="prefix">
      <joint name="${prefix}finger_joint" type="revolute">
        <origin xyz="0 -0.030601 0.054905" rpy="${pi / 2 + .725} 0 0" />
        <parent link="${prefix}robotiq_140_base_link" />
        <child link="${prefix}left_outer_knuckle" />
        <axis xyz="-1 0 0" />
        <limit lower="0" upper="0.7" velocity="2.0" effort="1000" />
      </joint>
      <xacro:finger_joints prefix="${prefix}" fingerprefix="left" reflect="1.0"/>
    </xacro:macro>

    <xacro:macro name="right_outer_knuckle_joint" params="prefix">
      <joint name="${prefix}right_outer_knuckle_joint" type="revolute">
        <origin xyz="0 0.030601 0.054905" rpy="${pi / 2 + .725} 0 ${pi}" />
        <parent link="${prefix}robotiq_140_base_link" />
        <child link="${prefix}right_outer_knuckle" />
        <axis xyz="1 0 0" />
        <limit lower="-0.725" upper="0.725" velocity="2.0" effort="1000" />
        <mimic joint="${prefix}finger_joint" multiplier="-1" offset="0" />
      </joint>
      <xacro:finger_joints prefix="${prefix}" fingerprefix="right" reflect="-1.0"/>
    </xacro:macro>

    <xacro:macro name="outer_finger_joint" params="prefix fingerprefix">
      <joint name="${prefix}${fingerprefix}_outer_finger_joint" type="fixed">
        <origin xyz="0 0.01821998610742 0.0260018192872234" rpy="0 0 0" />
        <parent link="${prefix}${fingerprefix}_outer_knuckle" />
        <child link="${prefix}${fingerprefix}_outer_finger" />
        <axis xyz="1 0 0" />
      </joint>
    </xacro:macro>

    <xacro:macro name="inner_knuckle_joint" params="prefix fingerprefix reflect">
      <joint name="${prefix}${fingerprefix}_inner_knuckle_joint" type="revolute">
        <origin xyz="0 ${reflect * -0.0127} 0.06142" rpy="${pi / 2 + .725} 0 ${(reflect - 1) * pi / 2}" />
        <parent link="${prefix}robotiq_140_base_link" />
        <child link="${prefix}${fingerprefix}_inner_knuckle" />
        <axis xyz="1 0 0" />
        <limit lower="-0.8757" upper="0.8757" velocity="2.0" effort="1000" />
        <mimic joint="${prefix}finger_joint" multiplier="-1" offset="0" />
      </joint>
    </xacro:macro>

    <xacro:macro name="inner_finger_joint" params="prefix fingerprefix">
      <joint name="${prefix}${fingerprefix}_inner_finger_joint" type="revolute">
        <origin xyz="0 0.0817554015893473 -0.0282203446692936" rpy="-0.725 0 0" />
        <parent link="${prefix}${fingerprefix}_outer_finger" />
        <child link="${prefix}${fingerprefix}_inner_finger" />
        <axis xyz="1 0 0" />
        <limit lower="-0.8757" upper="0.8757" velocity="2.0" effort="1000" />
        <mimic joint="${prefix}finger_joint" multiplier="1" offset="0" />
      </joint>
    </xacro:macro>

    <xacro:macro name="inner_finger_pad_joint" params="prefix fingerprefix">
      <joint name="${prefix}${fingerprefix}_inner_finger_pad_joint" type="fixed">
        <origin xyz="0 0.0457554015893473 -0.0272203446692936" rpy="0 0 0" />
        <parent link="${prefix}${fingerprefix}_inner_finger" />
        <child link="${prefix}${fingerprefix}_inner_finger_pad" />
        <axis xyz="0 0 1" />
      </joint>
    </xacro:macro>

    <xacro:macro name="finger_joints" params="prefix fingerprefix reflect">
      <xacro:outer_finger_joint prefix="${prefix}" fingerprefix="${fingerprefix}"/>
      <xacro:inner_knuckle_joint prefix="${prefix}" fingerprefix="${fingerprefix}" reflect="${reflect}"/>
      <xacro:inner_finger_joint prefix="${prefix}" fingerprefix="${fingerprefix}"/>
      <xacro:inner_finger_pad_joint prefix="${prefix}" fingerprefix="${fingerprefix}"/>
    </xacro:macro>

    <xacro:macro name="finger_links" params="prefix fingerprefix stroke">
      <xacro:outer_knuckle prefix="${prefix}" fingerprefix="${fingerprefix}" stroke="${stroke}"/>
      <xacro:outer_finger prefix="${prefix}" fingerprefix="${fingerprefix}" stroke="${stroke}"/>
      <xacro:inner_finger prefix="${prefix}" fingerprefix="${fingerprefix}" stroke="${stroke}"/>
      <xacro:inner_finger_pad prefix="${prefix}" fingerprefix="${fingerprefix}"/>
      <xacro:inner_knuckle prefix="${prefix}" fingerprefix="${fingerprefix}" stroke="${stroke}"/>
    </xacro:macro>

    <xacro:finger_links prefix="${prefix}" fingerprefix="left" stroke="140"/>
    <xacro:finger_links prefix="${prefix}" fingerprefix="right" stroke="140"/>
    <xacro:finger_joint prefix="${prefix}"/>
    <xacro:right_outer_knuckle_joint prefix="${prefix}"/>

    <!-- ROS2 Controls -->
    <xacro:if value="${use_controllers}">
      <ros2_control name="${name}_hardware" type="system">
        <!-- Plugins -->
        <hardware>
          <xacro:if value="${sim_isaac}">
            <plugin>topic_based_ros2_control/TopicBasedSystem</plugin>
            <param name="joint_commands_topic">${isaac_joint_commands}</param>
            <param name="joint_states_topic">${isaac_joint_states}</param>
          </xacro:if>
          <xacro:if value="${sim_gazebo}">
            <plugin>ign_ros2_control/IgnitionSystem</plugin>
          </xacro:if>
          <xacro:if value="${use_fake_hardware}">
            <plugin>mock_components/GenericSystem</plugin>
            <param name="mock_sensor_commands">${mock_sensor_commands}</param>
            <param name="state_following_offset">0.0</param>
          </xacro:if>
          <xacro:unless value="${use_fake_hardware or sim_gazebo or sim_isaac}">
            <plugin>robotiq_driver/RobotiqGripperHardwareInterface</plugin>
            <param name="gripper_closed_position">0.695</param>
            <param name="COM_port">${com_port}</param>
            <param name="gripper_speed_multiplier">1.0</param>
            <param name="gripper_force_multiplier">0.5</param>
          </xacro:unless>
        </hardware>

        <!-- Joint interfaces -->
        <!-- With Gazebo or Hardware, they handle mimic joints, so we only need this command interface activated -->
        <joint name="${prefix}finger_joint">
          <command_interface name="position" />
          <state_interface name="position">
            <param name="initial_value">0.695</param>
          </state_interface>
          <state_interface name="velocity"/>
        </joint>
        <!-- When simulating we need to include the rest of the gripper joints -->
        <xacro:if value="${use_fake_hardware or sim_isaac or sim_gazebo}">
          <joint name="${prefix}left_inner_knuckle_joint">
            <xacro:unless value="${sim_gazebo}">
              <state_interface name="position"/>
              <state_interface name="velocity"/>
            </xacro:unless>
          </joint>
          <joint name="${prefix}left_inner_finger_joint">
            <xacro:unless value="${sim_gazebo}">
              <state_interface name="position"/>
              <state_interface name="velocity"/>
            </xacro:unless>
          </joint>
          <joint name="${prefix}right_outer_knuckle_joint">
            <xacro:unless value="${sim_gazebo}">
              <state_interface name="position"/>
              <state_interface name="velocity"/>
            </xacro:unless>
          </joint>
          <joint name="${prefix}right_inner_knuckle_joint">
            <xacro:unless value="${sim_gazebo}">
              <state_interface name="position"/>
              <state_interface name="velocity"/>
            </xacro:unless>
          </joint>
          <joint name="${prefix}right_inner_finger_joint">
            <xacro:unless value="${sim_gazebo}">
              <state_interface name="position"/>
              <state_interface name="velocity"/>
            </xacro:unless>
          </joint>
        </xacro:if>

        <!-- Only add this with fake hardware mode -->
        <xacro:unless value="${sim_gazebo or sim_isaac}">
          <gpio name="reactivate_gripper">
            <command_interface name="reactivate_gripper_cmd" />
            <command_interface name="reactivate_gripper_response" />
          </gpio>
        </xacro:unless>
      </ros2_control>
    </xacro:if>

  </xacro:macro>
</robot>
